Workbook

Sheet How to use
A1: CRA gap checklist: Sprout S1
A2: Plain-English summary of the EU Cyber Resilience Act (Regulation (EU) 2024/2847) for small makers. Not the legal text and not legal advice.
A4: Client | B4: Mossbyte Labs BV (fictional)
A5: Product | B5: Sprout S1
A6: Prepared by | B6: Alex Example, Example Consulting (fictional)
A7: Status as of | B7: 2026-10-07
A9: How to fill it in
A10: 1. Work through the 'Checklist' sheet with the client, one area at a time (about 60 to 90 minutes).
A11: 2. Fill in only the yellow columns: Status, Evidence, Owner, Target date and Notes / gaps.
A12: 3. Status: pick from the list. Use 'Needs lawyer' for anything about scope, category, role or conformity.
A13: 4. Evidence: the file name or link that proves the item (for example 'vulnerability-report.xlsx, 2026-10-07').
A14: 5. The 'Summary' sheet counts progress per area by itself.
A16: What the statuses mean
A17: Not started: nothing in place yet.
A18: In progress: partly done, or done but not yet approved or published.
A19: Done: in place, with evidence you could show an authority.
A20: Needs lawyer: waiting for a legal answer. Do not guess.
A21: Not applicable: does not apply to this product; say why in Notes.
... A33: Example of a filled-in row
A34: ID | B34: Status | C34: Evidence (file or link) | D34: Owner | E34: Target date | F34: Notes / gaps
A35: P2 | B35: In progress | C35: vulnerability-report.xlsx (2026-10-07) | D35: Firmware lead | E35: 2026-11-30 | F35: 6 updates planned for release 2.4; 1 finding marked 'not affected'.

Sheet Summary
A1: Progress by area
A2: Counts update automatically from the Checklist sheet.
A4: Area | B4: Items | C4: Done | D4: In progress | E4: Not started | F4: Needs lawyer | G4: Not applicable | H4: Progress
A5: 1. Scope and roles | B5: =COUNTIF(Checklist!$B$2:$B$500,$A5) -> 5 | C5: =COUNTIFS(Checklist!$B$2:$B$500,$A5,Checklist!$G$2:$G$500,"Done") -> 0 | D5: =COUNTIFS(Checklist!$B$2:$B$500,$A5,Checklist!$G$2:$G$500,"In progress") -> 0 | E5: =COUNTIFS(Checklist!$B$2:$B$500,$A5,Checklist!$G$2:$G$500,"Not started") -> 0 | F5: =COUNTIFS(Checklist!$B$2:$B$500,$A5,Checklist!$G$2:$G$500,"Needs lawyer") -> 5 | G5: =COUNTIFS(Checklist!$B$2:$B$500,$A5,Checklist!$G$2:$G$500,"Not applicable") -> 0 | H5: =IFERROR(C5/(B5-G5),0) -> 0
A6: 2. Risk assessment and documentation | B6: =COUNTIF(Checklist!$B$2:$B$500,$A6) -> 6 | C6: =COUNTIFS(Checklist!$B$2:$B$500,$A6,Checklist!$G$2:$G$500,"Done") -> 1 | D6: =COUNTIFS(Checklist!$B$2:$B$500,$A6,Checklist!$G$2:$G$500,"In progress") -> 1 | E6: =COUNTIFS(Checklist!$B$2:$B$500,$A6,Checklist!$G$2:$G$500,"Not started") -> 3 | F6: =COUNTIFS(Checklist!$B$2:$B$500,$A6,Checklist!$G$2:$G$500,"Needs lawyer") -> 1 | G6: =COUNTIFS(Checklist!$B$2:$B$500,$A6,Checklist!$G$2:$G$500,"Not applicable") -> 0 | H6: =IFERROR(C6/(B6-G6),0) -> 0.166667
A7: 3. Secure by design (Annex I, Part I) | B7: =COUNTIF(Checklist!$B$2:$B$500,$A7) -> 14 | C7: =COUNTIFS(Checklist!$B$2:$B$500,$A7,Checklist!$G$2:$G$500,"Done") -> 5 | D7: =COUNTIFS(Checklist!$B$2:$B$500,$A7,Checklist!$G$2:$G$500,"In progress") -> 6 | E7: =COUNTIFS(Checklist!$B$2:$B$500,$A7,Checklist!$G$2:$G$500,"Not started") -> 3 | F7: =COUNTIFS(Checklist!$B$2:$B$500,$A7,Checklist!$G$2:$G$500,"Needs lawyer") -> 0 | G7: =COUNTIFS(Checklist!$B$2:$B$500,$A7,Checklist!$G$2:$G$500,"Not applicable") -> 0 | H7: =IFERROR(C7/(B7-G7),0) -> 0.357143
A8: 4. Vulnerability handling (Annex I, Part II) | B8: =COUNTIF(Checklist!$B$2:$B$500,$A8) -> 10 | C8: =COUNTIFS(Checklist!$B$2:$B$500,$A8,Checklist!$G$2:$G$500,"Done") -> 0 | D8: =COUNTIFS(Checklist!$B$2:$B$500,$A8,Checklist!$G$2:$G$500,"In progress") -> 6 | E8: =COUNTIFS(Checklist!$B$2:$B$500,$A8,Checklist!$G$2:$G$500,"Not started") -> 4 | F8: =COUNTIFS(Checklist!$B$2:$B$500,$A8,Checklist!$G$2:$G$500,"Needs lawyer") -> 0 | G8: =COUNTIFS(Checklist!$B$2:$B$500,$A8,Checklist!$G$2:$G$500,"Not applicable") -> 0 | H8: =IFERROR(C8/(B8-G8),0) -> 0
A9: 5. Reporting (applies since 11 September 2026) | B9: =COUNTIF(Checklist!$B$2:$B$500,$A9) -> 6 | C9: =COUNTIFS(Checklist!$B$2:$B$500,$A9,Checklist!$G$2:$G$500,"Done") -> 1 | D9: =COUNTIFS(Checklist!$B$2:$B$500,$A9,Checklist!$G$2:$G$500,"In progress") -> 4 | E9: =COUNTIFS(Checklist!$B$2:$B$500,$A9,Checklist!$G$2:$G$500,"Not started") -> 1 | F9: =COUNTIFS(Checklist!$B$2:$B$500,$A9,Checklist!$G$2:$G$500,"Needs lawyer") -> 0 | G9: =COUNTIFS(Checklist!$B$2:$B$500,$A9,Checklist!$G$2:$G$500,"Not applicable") -> 0 | H9: =IFERROR(C9/(B9-G9),0) -> 0.166667
A10: 6. Support period and updates | B10: =COUNTIF(Checklist!$B$2:$B$500,$A10) -> 4 | C10: =COUNTIFS(Checklist!$B$2:$B$500,$A10,Checklist!$G$2:$G$500,"Done") -> 0 | D10: =COUNTIFS(Checklist!$B$2:$B$500,$A10,Checklist!$G$2:$G$500,"In progress") -> 2 | E10: =COUNTIFS(Checklist!$B$2:$B$500,$A10,Checklist!$G$2:$G$500,"Not started") -> 2 | F10: =COUNTIFS(Checklist!$B$2:$B$500,$A10,Checklist!$G$2:$G$500,"Needs lawyer") -> 0 | G10: =COUNTIFS(Checklist!$B$2:$B$500,$A10,Checklist!$G$2:$G$500,"Not applicable") -> 0 | H10: =IFERROR(C10/(B10-G10),0) -> 0
A11: 7. Information for users (Annex II) | B11: =COUNTIF(Checklist!$B$2:$B$500,$A11) -> 9 | C11: =COUNTIFS(Checklist!$B$2:$B$500,$A11,Checklist!$G$2:$G$500,"Done") -> 2 | D11: =COUNTIFS(Checklist!$B$2:$B$500,$A11,Checklist!$G$2:$G$500,"In progress") -> 3 | E11: =COUNTIFS(Checklist!$B$2:$B$500,$A11,Checklist!$G$2:$G$500,"Not started") -> 3 | F11: =COUNTIFS(Checklist!$B$2:$B$500,$A11,Checklist!$G$2:$G$500,"Needs lawyer") -> 0 | G11: =COUNTIFS(Checklist!$B$2:$B$500,$A11,Checklist!$G$2:$G$500,"Not applicable") -> 1 | H11: =IFERROR(C11/(B11-G11),0) -> 0.25
A12: All areas | B12: =SUM(B5:B11) -> 54 | C12: =SUM(C5:C11) -> 9 | D12: =SUM(D5:D11) -> 22 | E12: =SUM(E5:E11) -> 16 | F12: =SUM(F5:F11) -> 6 | G12: =SUM(G5:G11) -> 1 | H12: =IFERROR(C12/(B12-G12),0) -> 0.169811
A14: Progress = Done ÷ (Items − Not applicable). 100% means every applicable item has evidence. It does not mean the product is CRA compliant.

Sheet Checklist
A1: ID | B1: Area | C1: Requirement (plain English) | D1: CRA reference | E1: What good evidence looks like | F1: Quick win for small makers | G1: Status | H1: Evidence (file or link) | I1: Owner | J1: Target date | K1: Notes / gaps
A2: S1 | B2: 1. Scope and roles | C2: Confirm whether the CRA applies to each product: is it hardware or software with a data connection, sold or supplied in the EU, and does any exclusion apply (for example medical devices, vehicles, or products covered by other EU sector rules)? | D2: Art. 2, Art. 3 | E2: A short written scope note per product from the lawyer. | F2: List every product and version you sell into the EU and how it connects (Wi-Fi, Bluetooth, app, cloud). Hand the list to the lawyer. | G2: Needs lawyer | I2: Pieter Claes (CEO) with the lawyer | J2: 2026-10-21 | K2: Lawyer meeting booked for 21 October. Product list and connection diagram sent.
A3: S2 | B3: 1. Scope and roles | C3: Confirm the product's category: default, important (class I or II) or critical. The category decides how conformity must be assessed. | D3: Art. 7, Art. 8, Annex III, Annex IV | E3: The lawyer's category decision with reasons. | F3: Write down the product's main function and any security features (locks, cameras, alarms, routers, password storage) for the lawyer. | G3: Needs lawyer | I3: Lawyer | J3: 2026-10-21 | K3: Plant sensor with no security function; the lawyer to confirm the category.
A4: S3 | B4: 1. Scope and roles | C4: Confirm your role for each product: manufacturer, importer or distributor. A company outside the EU should also decide who imports and whether to appoint an authorised representative in the EU. | D4: Art. 13, Art. 18 to 20 | E4: Role per product, confirmed by the lawyer. | F4: Note who designs the product, under whose name it is sold, and who brings it into the EU. | G4: Needs lawyer | I4: Lawyer | J4: 2026-10-21 | K4: Mossbyte designs the product and sells it under its own name from Belgium. Lawyer to confirm the role.
A5: S4 | B5: 1. Scope and roles | C5: Check which other EU rules apply at the same time, for example the cybersecurity rules for wireless products under the Radio Equipment Directive, data protection law (GDPR) and product safety rules. | D5: Other EU law | E5: List of applicable rules from the lawyer or test lab. | F5: If the product has Wi-Fi, Bluetooth, LoRa or mobile data, ask your test lab about the radio cybersecurity standards (EN 18031 series). | G5: Needs lawyer | I5: Lawyer and test lab | J5: 2026-11-15 | K5: Wi-Fi product: ask the test lab about the radio equipment cybersecurity standards (EN 18031 series).
A6: S5 | B6: 1. Scope and roles | C6: If the product needs a cloud service or app to do its job, ask whether that service counts as part of the product (remote data processing) and so must meet the same requirements. | D6: Art. 3 | E6: The lawyer's answer, recorded in the scope note. | F6: Draw a simple diagram: device, app, cloud, and which functions need which part. | G6: Needs lawyer | I6: Lawyer | J6: 2026-10-21 | K6: Watering alerts need Sprout Cloud. Is the cloud service part of the product?
A7: D1 | B7: 2. Risk assessment and documentation | C7: Carry out a cybersecurity risk assessment for the product, write it down, keep it up to date during the support period, and use it when designing, building, delivering and maintaining the product. | D7: Art. 13 | E7: Dated, versioned risk assessment that links risks to design decisions. | F7: Start with a one-page threat list: who might attack, through which interface, and what would go wrong for the user. | G7: In progress | H7: docs/risk/threat-list-v0.3 (internal) | I7: Mara Janssens (CTO) | J7: 2026-11-30 | K7: One-page threat list started. Needs a link to design decisions.
A8: D2 | B8: 2. Risk assessment and documentation | C8: Keep technical documentation: what the product is, its design and architecture, how vulnerabilities are handled, the risk assessment, how the support period was chosen, standards used, test reports and the SBOM. | D8: Art. 31, Annex VII | E8: A technical file folder with an index page. | F8: Create the folder now and file this readiness pack in it. | G8: Not started | I8: Mara Janssens (CTO) | J8: 2027-03-31 | K8: Create a technical file folder; file this pack in it.
A9: D3 | B9: 2. Risk assessment and documentation | C9: Keep the technical documentation and the EU declaration of conformity for at least 10 years after the product is placed on the market, or for the support period if that is longer. | D9: Art. 13 | E9: Archive location and retention rule written down. | F9: Use storage you control with backups, not a personal laptop. | G9: Not started | I9: Pieter Claes (CEO) | J9: 2027-03-31
A10: D4 | B10: 2. Risk assessment and documentation | C10: Choose and complete the conformity assessment route that fits the product's category. Default-category products can usually use self-assessment; other categories may need harmonised standards or a notified body. | D10: Art. 32 | E10: Conformity assessment record. | F10: Ask the lawyer early, because notified bodies can have waiting lists. | G10: Needs lawyer | I10: Lawyer | J10: 2027-06-30 | K10: Route depends on the category (S2).
A11: D5 | B11: 2. Risk assessment and documentation | C11: After the conformity assessment, draw up and sign the EU declaration of conformity and put the CE marking on the product. The manufacturer signs it, never an outside consultant. | D11: Art. 28 to 30, Annex V | E11: Signed declaration of conformity; CE marking on product or packaging. | F11: Not before the other items are done. Plan it for well before 11 December 2027 (verify current dates). | G11: Not started | I11: Pieter Claes (CEO) | J11: 2027-09-30 | K11: Only after the conformity assessment. Mossbyte signs, not the consultant.
A12: D6 | B12: 2. Risk assessment and documentation | C12: Mark the product with its type and a batch or serial number, and give the manufacturer's name, postal address and electronic contact on the product, packaging or accompanying document. | D12: Art. 13 | E12: Label artwork; packaging; manual. | F12: Check the current label and box against this list. | G12: Done | H12: Device label artwork v4; box artwork v2 | I12: Lina Haddad (firmware lead) | K12: Model and serial number on the label; address and email on the box.
A13: P1 | B13: 3. Secure by design (Annex I, Part I) | C13: Design, build and produce the product so its level of security matches the risks found in the risk assessment. | D13: Annex I Part I (1) | E13: Risk assessment linked to design decisions and tests. | F13: Pick the three biggest risks and note what the product already does about each. | G13: In progress | H13: Threat list (D1) | I13: Mara Janssens (CTO) | J13: 2026-12-31
A14: P2 | B14: 3. Secure by design (Annex I, Part I) | C14: Put each release on the market without known exploitable vulnerabilities: check its components against vulnerability databases first, then fix each finding or record why it cannot be exploited. | D14: Annex I Part I (2)(a) | E14: SBOM and vulnerability report for each release, with a decision for every open finding. | F14: Run make_sbom and vuln_report as a fixed step of every release. | G14: In progress | H14: vulnerability-report.xlsx (2026-10-07) | I14: Tom Willems (backend) | J14: 2026-11-30 | K14: 6 updates planned for release 2.4. Firmware components still need a manual check.
A15: P3 | B15: 3. Secure by design (Annex I, Part I) | C15: Ship with secure default settings (no shared default passwords, unneeded services switched off) and let users reset the product to its original state. | D15: Annex I Part I (2)(b) | E15: List of default settings; factory reset instructions. | F15: Unique password per device, or force the user to set one on first use. | G15: Done | H15: Set-up guide, page 2; factory reset test log | I15: Lina Haddad (firmware lead) | K15: Unique set-up code per device on the label. Factory reset: hold the button for 10 seconds.
A16: P4 | B16: 3. Secure by design (Annex I, Part I) | C16: Make sure vulnerabilities can be fixed through security updates. Where it suits the product, install security updates automatically by default with an easy opt-out, tell users about available updates, and let them postpone an update for a while. | D16: Annex I Part I (2)(c) | E16: Description of the update mechanism; screenshots of the settings. | F16: If updates are manual today, plan automatic security updates for the next major release. | G16: In progress | I16: Lina Haddad (firmware lead) | J16: 2027-03-31 | K16: OTA updates exist and are signed. Automatic install with postpone option is in release 2.4.
A17: P5 | B17: 3. Secure by design (Annex I, Part I) | C17: Protect against unauthorised access with suitable controls such as authentication and access management, and report possible unauthorised access. | D17: Annex I Part I (2)(d) | E17: Authentication design; logging or alerts for failed log-ins. | F17: Limit log-in attempts and log the failures. | G17: In progress | I17: Tom Willems (backend) | J17: 2026-12-31 | K17: Cloud log-in is rate-limited. Failed log-ins are not yet logged.
A18: P6 | B18: 3. Secure by design (Annex I, Part I) | C18: Keep data confidential, whether stored, sent or processed, personal or not, for example with current encryption at rest and in transit. | D18: Annex I Part I (2)(e) | E18: TLS settings; notes on how stored data and keys are protected. | F18: Use TLS 1.2 or newer for every connection, and keep no secrets in plain text in firmware. | G18: Done | H18: TLS settings note (internal) | I18: Tom Willems (backend) | K18: TLS 1.2+ for all connections; Wi-Fi credentials stored in encrypted flash.
A19: P7 | B19: 3. Secure by design (Annex I, Part I) | C19: Protect data, commands, programs and settings against unauthorised changes and report corruption, for example with signed firmware and secure boot. | D19: Annex I Part I (2)(f) | E19: Firmware signing and verification process. | F19: Sign firmware images and check the signature before installing them. | G19: In progress | I19: Lina Haddad (firmware lead) | J19: 2027-03-31 | K19: Firmware images are signed. Secure boot is not enabled yet.
A20: P8 | B20: 3. Secure by design (Annex I, Part I) | C20: Process only the data that is needed for the product's intended purpose (data minimisation). | D20: Annex I Part I (2)(g) | E20: Data inventory: what is collected, where it goes, and why. | F20: List every data field the device and app send, and drop what is not needed. | G20: Done | H20: Data inventory (internal) | I20: Mara Janssens (CTO) | K20: Collects soil moisture, light level and device ID only.
A21: P9 | B21: 3. Secure by design (Annex I, Part I) | C21: Keep essential functions available, also after an incident, for example by being resilient against denial-of-service attacks. | D21: Annex I Part I (2)(h) | E21: Test notes, including how the product behaves when the cloud is down. | F21: Make sure the core function keeps working when the internet or cloud is unavailable. | G21: Done | H21: Offline test notes | I21: Lina Haddad (firmware lead) | K21: Sensor keeps 7 days of readings when the cloud is unreachable.
A22: P10 | B22: 3. Secure by design (Annex I, Part I) | C22: Limit the harm the product can cause to other devices and networks, for example traffic floods or aggressive retries. | D22: Annex I Part I (2)(i) | E22: Network behaviour notes; retry and rate limits. | F22: Add back-off and limits to every reconnect and retry loop. | G22: Not started | I22: Lina Haddad (firmware lead) | J22: 2027-03-31 | K22: Check reconnect back-off in the firmware.
A23: P11 | B23: 3. Secure by design (Annex I, Part I) | C23: Keep the attack surface small, including external interfaces: close unused ports and services, and disable debug interfaces on production units. | D23: Annex I Part I (2)(j) | E23: List of open interfaces and ports per part, with reasons. | F23: Disable JTAG and serial debug access and remove test endpoints in production builds. | G23: In progress | I23: Lina Haddad (firmware lead) | J23: 2026-12-31 | K23: Serial console is off in release builds; JTAG is still enabled. Fix in release 2.4.
A24: P12 | B24: 3. Secure by design (Annex I, Part I) | C24: Reduce the impact of an incident with exploit mitigation techniques, for example memory protection, least privilege and separating components. | D24: Annex I Part I (2)(k) | E24: Build settings and design notes showing the mitigations used. | F24: Turn on the compiler and platform protections your SDK offers (stack protection, memory protection). | G24: Not started | I24: Lina Haddad (firmware lead) | J24: 2027-06-30
A25: P13 | B25: 3. Secure by design (Annex I, Part I) | C25: Record and monitor relevant security events, such as access to or changes of data, services or functions, and let users opt out. | D25: Annex I Part I (2)(l) | E25: Logging design; where logs go and how long they are kept. | F25: Log log-ins, setting changes and update installs in the cloud service. | G25: Not started | I25: Tom Willems (backend) | J25: 2027-03-31
A26: P14 | B26: 3. Secure by design (Annex I, Part I) | C26: Let users delete all their data and settings securely and permanently, and move data to another product or system securely where that is possible. | D26: Annex I Part I (2)(m) | E26: Factory reset and account deletion instructions; test result. | F26: Make the factory reset wipe keys, Wi-Fi credentials and user data, and test it. | G26: Done | H26: Factory reset test log | I26: Lina Haddad (firmware lead) | K26: Factory reset wipes keys, Wi-Fi credentials and stored readings.
A27: V1 | B27: 4. Vulnerability handling (Annex I, Part II) | C27: Identify and document the product's components and vulnerabilities, including an SBOM in a common machine-readable format that covers at least the top-level dependencies. | D27: Annex I Part II (1) | E27: CycloneDX SBOM per release, confirmed by the manufacturer. | F27: Use this kit's make_sbom script for every release. | G27: In progress | H27: sbom/sprout-s1-2.3.0.cdx.json | I27: Mara Janssens (CTO) | J27: 2026-10-21 | K27: Waiting for Mossbyte to confirm the SBOM matches the shipped release.
A28: V2 | B28: 4. Vulnerability handling (Annex I, Part II) | C28: Fix vulnerabilities without delay, in line with the risk, by providing security updates. Where technically possible, ship security fixes separately from new features. | D28: Annex I Part II (2) | E28: Release notes showing security-only updates; fix-time records. | F28: Agree internal fix targets by severity (see the policy). | G28: In progress | I28: Mara Janssens (CTO) | J28: 2026-12-31 | K28: Fix targets agreed in the policy draft.
A29: V3 | B29: 4. Vulnerability handling (Annex I, Part II) | C29: Test and review the product's security effectively and regularly. | D29: Annex I Part II (3) | E29: Test plan; monthly dependency checks; review notes; penetration test report if any. | F29: Monthly dependency check plus a short security review before each release. | G29: In progress | H29: Monthly check (monthly care plan) | I29: Tom Willems (backend) | J29: 2026-11-30 | K29: Monthly dependency check starts in November.
A30: V4 | B30: 4. Vulnerability handling (Annex I, Part II) | C30: Once a fix is available, publish information about the fixed vulnerability: what it was, which products and versions are affected, the impact, the severity and how users can fix it. In justified cases you may wait until users have had the chance to update. | D30: Annex I Part II (4) | E30: Security advisories page with past advisories. | F30: Create a simple 'Security advisories' page on the website. | G30: Not started | I30: Sofie Peeters (customer care) | J30: 2026-12-15 | K30: Create a 'Security advisories' page.
A31: V5 | B31: 4. Vulnerability handling (Annex I, Part II) | C31: Have a coordinated vulnerability disclosure policy and actually follow it. | D31: Annex I Part II (5) | E31: Published policy; log of reports handled under it. | F31: Publish the policy from this kit after the lawyer has read it. | G31: In progress | H31: vulnerability-handling-policy.docx (draft) | I31: Pieter Claes (CEO) | J31: 2026-11-01 | K31: Lawyer to review the safe-harbour wording before publishing.
A32: V6 | B32: 4. Vulnerability handling (Annex I, Part II) | C32: Make it easy to report vulnerabilities in the product and in the third-party components it contains, including a contact address for reports. | D32: Annex I Part II (6) | E32: security.txt, security web page, monitored mailbox. | F32: Publish security.txt and check the mailbox every working day. | G32: In progress | H32: security.txt (ready to publish) | I32: Tom Willems (backend) | J32: 2026-11-01 | K32: Publish together with the policy.
A33: V7 | B33: 4. Vulnerability handling (Annex I, Part II) | C33: Distribute updates securely (for example signed, over encrypted connections) so fixes reach users in time, and automatically where that applies to security updates. | D33: Annex I Part II (7) | E33: Update distribution design; signing key management. | F33: Keep the signing key off developer laptops, for example in a hardware token or a secrets manager. | G33: In progress | I33: Lina Haddad (firmware lead) | J33: 2027-03-31 | K33: Signed OTA over TLS. Signing key is on a laptop: move it to a hardware token.
A34: V8 | B34: 4. Vulnerability handling (Annex I, Part II) | C34: Release security updates without delay and free of charge (unless otherwise agreed with a business customer for a tailor-made product), with a message telling users what the update fixes and what to do. | D34: Annex I Part II (8) | E34: Update notes and user messages for past security updates. | F34: Write a short template for security update notes. | G34: Not started | I34: Sofie Peeters (customer care) | J34: 2026-12-15 | K34: Write a template for security update notes.
A35: V9 | B35: 4. Vulnerability handling (Annex I, Part II) | C35: When you find a vulnerability in a third-party or open-source component, report it to whoever maintains that component, and share your fix with them where appropriate. | D35: Art. 13 | E35: Copies of reports sent to component maintainers. | F35: Add 'tell the upstream maintainer' as a step in the runbook. | G35: Not started | I35: Lina Haddad (firmware lead) | J35: 2026-12-31 | K35: Add an 'upstream report' step to the release checklist.
A36: V10 | B36: 4. Vulnerability handling (Annex I, Part II) | C36: Take care when choosing third-party components, including open source, so they do not weaken the product's security. | D36: Art. 13 | E36: Short notes on why each major component was chosen (maintained, no known vulnerabilities, licence fits). | F36: Before adding a new library, check its last release date and known vulnerabilities. | G36: Not started | I36: Mara Janssens (CTO) | J36: 2027-03-31
A37: R1 | B37: 5. Reporting (applies since 11 September 2026) | C37: Know where and how to report: get access to ENISA's single reporting platform and find out which national CSIRT acts as your coordinator. | D37: Art. 14, Art. 16 | E37: Completed 'Before you need it' section of the runbook; access tested. | F37: Request platform access for the incident lead and the deputy now, not during an incident. | G37: In progress | I37: Mara Janssens (CTO) | J37: 2026-10-31 | K37: Platform access requested for Mara and Lina.
A38: R2 | B38: 5. Reporting (applies since 11 September 2026) | C38: Be ready to report actively exploited vulnerabilities: early warning within 24 hours, notification within 72 hours, final report within 14 days after a fix or mitigation is available. | D38: Art. 14 | E38: Reporting runbook; notes from a practice run. | F38: Run a one-hour tabletop exercise with the runbook. | G38: In progress | H38: reporting-runbook.docx (draft) | I38: Mara Janssens (CTO) | J38: 2026-11-18 | K38: Practice run planned for 18 November.
A39: R3 | B39: 5. Reporting (applies since 11 September 2026) | C39: Be ready to report severe incidents that affect the product's security: early warning within 24 hours, notification within 72 hours, final report within one month after the notification. | D39: Art. 14 | E39: Reporting runbook; notes from a practice run. | F39: Agree with your hosting provider how they will tell you about incidents. | G39: In progress | H39: reporting-runbook.docx (draft) | I39: Mara Janssens (CTO) | J39: 2026-11-18 | K39: Ask the hosting provider how they report incidents.
A40: R4 | B40: 5. Reporting (applies since 11 September 2026) | C40: After an actively exploited vulnerability or severe incident, inform affected users (and all users where appropriate) about the problem and what they can do, using a structured, machine-readable format as well as plain language. | D40: Art. 14 | E40: User notice template; advisory format (for example CSAF). | F40: Prepare a user notice template now (see the runbook). | G40: Not started | I40: Sofie Peeters (customer care) | J40: 2026-11-30 | K40: User notice template is in the runbook; decide the CSAF tooling.
...
